[2025-10-05T20:47:36.992+0000] {local_task_job_runner.py:123} INFO - ::group::Pre task execution logs
[2025-10-05T20:47:36.997+0000] {taskinstance.py:2612} INFO - Dependencies all met for dep_context=non-requeueable deps ti=<TaskInstance: stocks_prediction_analysis.train manual__2025-10-05T20:43:09.956195+00:00 [queued]>
[2025-10-05T20:47:36.999+0000] {taskinstance.py:2612} INFO - Dependencies all met for dep_context=requeueable deps ti=<TaskInstance: stocks_prediction_analysis.train manual__2025-10-05T20:43:09.956195+00:00 [queued]>
[2025-10-05T20:47:36.999+0000] {taskinstance.py:2865} INFO - Starting attempt 1 of 1
[2025-10-05T20:47:37.003+0000] {taskinstance.py:2888} INFO - Executing <Task(_PythonDecoratedOperator): train> on 2025-10-05 20:43:09.956195+00:00
[2025-10-05T20:47:37.006+0000] {logging_mixin.py:190} WARNING - /home/***/.local/lib/python3.12/site-packages/***/task/task_runner/standard_task_runner.py:70 DeprecationWarning: This process (pid=40444) is multi-threaded, use of fork() may lead to deadlocks in the child.
[2025-10-05T20:47:37.007+0000] {standard_task_runner.py:72} INFO - Started process 40447 to run task
[2025-10-05T20:47:37.007+0000] {standard_task_runner.py:104} INFO - Running: ['***', 'tasks', 'run', 'stocks_prediction_analysis', 'train', 'manual__2025-10-05T20:43:09.956195+00:00', '--job-id', '78', '--raw', '--subdir', 'DAGS_FOLDER/lab1.py', '--cfg-path', '/tmp/tmpio8cf181']
[2025-10-05T20:47:37.008+0000] {standard_task_runner.py:105} INFO - Job 78: Subtask train
[2025-10-05T20:47:37.117+0000] {task_command.py:467} INFO - Running <TaskInstance: stocks_prediction_analysis.train manual__2025-10-05T20:43:09.956195+00:00 [running]> on host b99170a1b783
[2025-10-05T20:47:37.138+0000] {taskinstance.py:3131} INFO - Exporting env vars: AIRFLOW_CTX_DAG_OWNER='***' AIRFLOW_CTX_DAG_ID='stocks_prediction_analysis' AIRFLOW_CTX_TASK_ID='train' AIRFLOW_CTX_EXECUTION_DATE='2025-10-05T20:43:09.956195+00:00' AIRFLOW_CTX_TRY_NUMBER='1' AIRFLOW_CTX_DAG_RUN_ID='manual__2025-10-05T20:43:09.956195+00:00'
[2025-10-05T20:47:37.139+0000] {taskinstance.py:731} INFO - ::endgroup::
[2025-10-05T20:47:37.142+0000] {base.py:84} INFO - Retrieving connection 'snowflake_conn'
[2025-10-05T20:47:37.142+0000] {connection.py:413} INFO - Snowflake Connector for Python Version: 3.12.1, Python Version: 3.12.5, Platform: Linux-6.10.14-linuxkit-aarch64-with-glibc2.36
[2025-10-05T20:47:37.143+0000] {connection.py:1196} INFO - Connecting to GLOBAL Snowflake domain
[2025-10-05T20:47:37.143+0000] {connection.py:1277} INFO - This connection is in OCSP Fail Open Mode. TLS Certificates would be checked for validity and revocation status. Any other Certificate Revocation related exceptions or OCSP Responder failures would be disregarded in favor of connectivity.
[2025-10-05T20:47:37.933+0000] {cursor.py:1156} INFO - Number of results in first chunk: 1
[2025-10-05T20:47:37.934+0000] {connection.py:788} INFO - closed
[2025-10-05T20:47:37.989+0000] {connection.py:794} INFO - No async queries seem to be running, deleting session
[2025-10-05T20:47:38.058+0000] {taskinstance.py:3310} ERROR - Task failed with exception
Traceback (most recent call last):
  File "/home/airflow/.local/lib/python3.12/site-packages/airflow/models/taskinstance.py", line 767, in _execute_task
    result = _execute_callable(context=context, **execute_callable_kwargs)
             ^^^^^^^^^^^^^^^^^^^^^^^^^^^^^^^^^^^^^^^^^^^^^^^^^^^^^^^^^^^^^
  File "/home/airflow/.local/lib/python3.12/site-packages/airflow/models/taskinstance.py", line 733, in _execute_callable
    return ExecutionCallableRunner(
           ^^^^^^^^^^^^^^^^^^^^^^^^
  File "/home/airflow/.local/lib/python3.12/site-packages/airflow/utils/operator_helpers.py", line 252, in run
    return self.func(*args, **kwargs)
           ^^^^^^^^^^^^^^^^^^^^^^^^^^
  File "/home/airflow/.local/lib/python3.12/site-packages/airflow/models/baseoperator.py", line 406, in wrapper
    return func(self, *args, **kwargs)
           ^^^^^^^^^^^^^^^^^^^^^^^^^^^
  File "/home/airflow/.local/lib/python3.12/site-packages/airflow/decorators/base.py", line 266, in execute
    return_value = super().execute(context)
                   ^^^^^^^^^^^^^^^^^^^^^^^^
  File "/home/airflow/.local/lib/python3.12/site-packages/airflow/models/baseoperator.py", line 406, in wrapper
    return func(self, *args, **kwargs)
           ^^^^^^^^^^^^^^^^^^^^^^^^^^^
  File "/home/airflow/.local/lib/python3.12/site-packages/airflow/operators/python.py", line 238, in execute
    return_value = self.execute_callable()
                   ^^^^^^^^^^^^^^^^^^^^^^^
  File "/home/airflow/.local/lib/python3.12/site-packages/airflow/operators/python.py", line 256, in execute_callable
    return runner.run(*self.op_args, **self.op_kwargs)
           ^^^^^^^^^^^^^^^^^^^^^^^^^^^^^^^^^^^^^^^^^^^
  File "/home/airflow/.local/lib/python3.12/site-packages/airflow/utils/operator_helpers.py", line 252, in run
    return self.func(*args, **kwargs)
           ^^^^^^^^^^^^^^^^^^^^^^^^^^
  File "/opt/airflow/dags/lab1.py", line 111, in train
    cursor.execute(create_view_sql)
  File "/home/airflow/.local/lib/python3.12/site-packages/snowflake/connector/cursor.py", line 1087, in execute
    Error.errorhandler_wrapper(self.connection, self, error_class, errvalue)
  File "/home/airflow/.local/lib/python3.12/site-packages/snowflake/connector/errors.py", line 284, in errorhandler_wrapper
    handed_over = Error.hand_to_other_handler(
                  ^^^^^^^^^^^^^^^^^^^^^^^^^^^^
  File "/home/airflow/.local/lib/python3.12/site-packages/snowflake/connector/errors.py", line 339, in hand_to_other_handler
    cursor.errorhandler(connection, cursor, error_class, error_value)
  File "/home/airflow/.local/lib/python3.12/site-packages/snowflake/connector/errors.py", line 215, in default_errorhandler
    raise error_class(
snowflake.connector.errors.ProgrammingError: 090106 (22000): 01bf839f-0306-9492-000f-c0df003b2c92: Cannot perform CREATE VIEW. This session does not have a current schema. Call 'USE SCHEMA', or use a qualified name.
[2025-10-05T20:47:38.068+0000] {taskinstance.py:1225} INFO - Marking task as FAILED. dag_id=stocks_prediction_analysis, task_id=train, run_id=manual__2025-10-05T20:43:09.956195+00:00, execution_date=20251005T204309, start_date=20251005T204736, end_date=20251005T204738
[2025-10-05T20:47:38.076+0000] {taskinstance.py:340} INFO - ::group::Post task execution logs
[2025-10-05T20:47:38.076+0000] {standard_task_runner.py:124} ERROR - Failed to execute job 78 for task train (090106 (22000): 01bf839f-0306-9492-000f-c0df003b2c92: Cannot perform CREATE VIEW. This session does not have a current schema. Call 'USE SCHEMA', or use a qualified name.; 40447)
Traceback (most recent call last):
  File "/home/airflow/.local/lib/python3.12/site-packages/airflow/task/task_runner/standard_task_runner.py", line 117, in _start_by_fork
    ret = args.func(args, dag=self.dag)
          ^^^^^^^^^^^^^^^^^^^^^^^^^^^^^
  File "/home/airflow/.local/lib/python3.12/site-packages/airflow/cli/cli_config.py", line 49, in command
    return func(*args, **kwargs)
           ^^^^^^^^^^^^^^^^^^^^^
  File "/home/airflow/.local/lib/python3.12/site-packages/airflow/utils/cli.py", line 115, in wrapper
    return f(*args, **kwargs)
           ^^^^^^^^^^^^^^^^^^
  File "/home/airflow/.local/lib/python3.12/site-packages/airflow/cli/commands/task_command.py", line 483, in task_run
    task_return_code = _run_task_by_selected_method(args, _dag, ti)
                       ^^^^^^^^^^^^^^^^^^^^^^^^^^^^^^^^^^^^^^^^^^^^
  File "/home/airflow/.local/lib/python3.12/site-packages/airflow/cli/commands/task_command.py", line 256, in _run_task_by_selected_method
    return _run_raw_task(args, ti)
           ^^^^^^^^^^^^^^^^^^^^^^^
  File "/home/airflow/.local/lib/python3.12/site-packages/airflow/cli/commands/task_command.py", line 341, in _run_raw_task
    return ti._run_raw_task(
           ^^^^^^^^^^^^^^^^^
  File "/home/airflow/.local/lib/python3.12/site-packages/airflow/utils/session.py", line 97, in wrapper
    return func(*args, session=session, **kwargs)
           ^^^^^^^^^^^^^^^^^^^^^^^^^^^^^^^^^^^^^^
  File "/home/airflow/.local/lib/python3.12/site-packages/airflow/models/taskinstance.py", line 3004, in _run_raw_task
    return _run_raw_task(
           ^^^^^^^^^^^^^^
  File "/home/airflow/.local/lib/python3.12/site-packages/airflow/models/taskinstance.py", line 273, in _run_raw_task
    TaskInstance._execute_task_with_callbacks(
  File "/home/airflow/.local/lib/python3.12/site-packages/airflow/models/taskinstance.py", line 3158, in _execute_task_with_callbacks
    result = self._execute_task(context, task_orig)
             ^^^^^^^^^^^^^^^^^^^^^^^^^^^^^^^^^^^^^^
  File "/home/airflow/.local/lib/python3.12/site-packages/airflow/models/taskinstance.py", line 3182, in _execute_task
    return _execute_task(self, context, task_orig)
           ^^^^^^^^^^^^^^^^^^^^^^^^^^^^^^^^^^^^^^^
  File "/home/airflow/.local/lib/python3.12/site-packages/airflow/models/taskinstance.py", line 767, in _execute_task
    result = _execute_callable(context=context, **execute_callable_kwargs)
             ^^^^^^^^^^^^^^^^^^^^^^^^^^^^^^^^^^^^^^^^^^^^^^^^^^^^^^^^^^^^^
  File "/home/airflow/.local/lib/python3.12/site-packages/airflow/models/taskinstance.py", line 733, in _execute_callable
    return ExecutionCallableRunner(
           ^^^^^^^^^^^^^^^^^^^^^^^^
  File "/home/airflow/.local/lib/python3.12/site-packages/airflow/utils/operator_helpers.py", line 252, in run
    return self.func(*args, **kwargs)
           ^^^^^^^^^^^^^^^^^^^^^^^^^^
  File "/home/airflow/.local/lib/python3.12/site-packages/airflow/models/baseoperator.py", line 406, in wrapper
    return func(self, *args, **kwargs)
           ^^^^^^^^^^^^^^^^^^^^^^^^^^^
  File "/home/airflow/.local/lib/python3.12/site-packages/airflow/decorators/base.py", line 266, in execute
    return_value = super().execute(context)
                   ^^^^^^^^^^^^^^^^^^^^^^^^
  File "/home/airflow/.local/lib/python3.12/site-packages/airflow/models/baseoperator.py", line 406, in wrapper
    return func(self, *args, **kwargs)
           ^^^^^^^^^^^^^^^^^^^^^^^^^^^
  File "/home/airflow/.local/lib/python3.12/site-packages/airflow/operators/python.py", line 238, in execute
    return_value = self.execute_callable()
                   ^^^^^^^^^^^^^^^^^^^^^^^
  File "/home/airflow/.local/lib/python3.12/site-packages/airflow/operators/python.py", line 256, in execute_callable
    return runner.run(*self.op_args, **self.op_kwargs)
           ^^^^^^^^^^^^^^^^^^^^^^^^^^^^^^^^^^^^^^^^^^^
  File "/home/airflow/.local/lib/python3.12/site-packages/airflow/utils/operator_helpers.py", line 252, in run
    return self.func(*args, **kwargs)
           ^^^^^^^^^^^^^^^^^^^^^^^^^^
  File "/opt/airflow/dags/lab1.py", line 111, in train
    cursor.execute(create_view_sql)
  File "/home/airflow/.local/lib/python3.12/site-packages/snowflake/connector/cursor.py", line 1087, in execute
    Error.errorhandler_wrapper(self.connection, self, error_class, errvalue)
  File "/home/airflow/.local/lib/python3.12/site-packages/snowflake/connector/errors.py", line 284, in errorhandler_wrapper
    handed_over = Error.hand_to_other_handler(
                  ^^^^^^^^^^^^^^^^^^^^^^^^^^^^
  File "/home/airflow/.local/lib/python3.12/site-packages/snowflake/connector/errors.py", line 339, in hand_to_other_handler
    cursor.errorhandler(connection, cursor, error_class, error_value)
  File "/home/airflow/.local/lib/python3.12/site-packages/snowflake/connector/errors.py", line 215, in default_errorhandler
    raise error_class(
snowflake.connector.errors.ProgrammingError: 090106 (22000): 01bf839f-0306-9492-000f-c0df003b2c92: Cannot perform CREATE VIEW. This session does not have a current schema. Call 'USE SCHEMA', or use a qualified name.
[2025-10-05T20:47:38.089+0000] {local_task_job_runner.py:266} INFO - Task exited with return code 1
[2025-10-05T20:47:38.182+0000] {taskinstance.py:3900} INFO - 0 downstream tasks scheduled from follow-on schedule check
[2025-10-05T20:47:38.184+0000] {local_task_job_runner.py:245} INFO - ::endgroup::
