[2025-10-06T19:21:39.492+0000] {local_task_job_runner.py:123} INFO - ::group::Pre task execution logs
[2025-10-06T19:21:39.498+0000] {taskinstance.py:2612} INFO - Dependencies all met for dep_context=non-requeueable deps ti=<TaskInstance: stocks_prediction_analysis.load_records manual__2025-10-06T19:21:36.081433+00:00 [queued]>
[2025-10-06T19:21:39.502+0000] {taskinstance.py:2612} INFO - Dependencies all met for dep_context=requeueable deps ti=<TaskInstance: stocks_prediction_analysis.load_records manual__2025-10-06T19:21:36.081433+00:00 [queued]>
[2025-10-06T19:21:39.502+0000] {taskinstance.py:2865} INFO - Starting attempt 1 of 1
[2025-10-06T19:21:39.506+0000] {taskinstance.py:2888} INFO - Executing <Task(_PythonDecoratedOperator): load_records> on 2025-10-06 19:21:36.081433+00:00
[2025-10-06T19:21:39.511+0000] {logging_mixin.py:190} WARNING - /home/***/.local/lib/python3.12/site-packages/***/task/task_runner/standard_task_runner.py:70 DeprecationWarning: This process (pid=46306) is multi-threaded, use of fork() may lead to deadlocks in the child.
[2025-10-06T19:21:39.511+0000] {standard_task_runner.py:72} INFO - Started process 46312 to run task
[2025-10-06T19:21:39.511+0000] {standard_task_runner.py:104} INFO - Running: ['***', 'tasks', 'run', 'stocks_prediction_analysis', 'load_records', 'manual__2025-10-06T19:21:36.081433+00:00', '--job-id', '101', '--raw', '--subdir', 'DAGS_FOLDER/lab1.py', '--cfg-path', '/tmp/tmpzv4uza89']
[2025-10-06T19:21:39.512+0000] {standard_task_runner.py:105} INFO - Job 101: Subtask load_records
[2025-10-06T19:21:39.628+0000] {task_command.py:467} INFO - Running <TaskInstance: stocks_prediction_analysis.load_records manual__2025-10-06T19:21:36.081433+00:00 [running]> on host b99170a1b783
[2025-10-06T19:21:39.688+0000] {taskinstance.py:3131} INFO - Exporting env vars: AIRFLOW_CTX_DAG_OWNER='***' AIRFLOW_CTX_DAG_ID='stocks_prediction_analysis' AIRFLOW_CTX_TASK_ID='load_records' AIRFLOW_CTX_EXECUTION_DATE='2025-10-06T19:21:36.081433+00:00' AIRFLOW_CTX_TRY_NUMBER='1' AIRFLOW_CTX_DAG_RUN_ID='manual__2025-10-06T19:21:36.081433+00:00'
[2025-10-06T19:21:39.689+0000] {taskinstance.py:731} INFO - ::endgroup::
[2025-10-06T19:21:39.693+0000] {base.py:84} INFO - Retrieving connection 'snowflake_conn'
[2025-10-06T19:21:39.695+0000] {connection.py:413} INFO - Snowflake Connector for Python Version: 3.12.1, Python Version: 3.12.5, Platform: Linux-6.10.14-linuxkit-aarch64-with-glibc2.36
[2025-10-06T19:21:39.695+0000] {connection.py:1196} INFO - Connecting to GLOBAL Snowflake domain
[2025-10-06T19:21:39.695+0000] {connection.py:1277} INFO - This connection is in OCSP Fail Open Mode. TLS Certificates would be checked for validity and revocation status. Any other Certificate Revocation related exceptions or OCSP Responder failures would be disregarded in favor of connectivity.
[2025-10-06T19:21:40.330+0000] {base.py:84} INFO - Retrieving connection 'snowflake_conn'
[2025-10-06T19:21:40.331+0000] {connection.py:413} INFO - Snowflake Connector for Python Version: 3.12.1, Python Version: 3.12.5, Platform: Linux-6.10.14-linuxkit-aarch64-with-glibc2.36
[2025-10-06T19:21:40.331+0000] {connection.py:1196} INFO - Connecting to GLOBAL Snowflake domain
[2025-10-06T19:21:40.332+0000] {connection.py:1277} INFO - This connection is in OCSP Fail Open Mode. TLS Certificates would be checked for validity and revocation status. Any other Certificate Revocation related exceptions or OCSP Responder failures would be disregarded in favor of connectivity.
[2025-10-06T19:21:41.126+0000] {cursor.py:1156} INFO - Number of results in first chunk: 1
[2025-10-06T19:21:41.246+0000] {cursor.py:1156} INFO - Number of results in first chunk: 1
[2025-10-06T19:21:41.247+0000] {connection.py:788} INFO - closed
[2025-10-06T19:21:41.367+0000] {connection.py:794} INFO - No async queries seem to be running, deleting session
[2025-10-06T19:29:30.673+0000] {cursor.py:1156} INFO - Number of results in first chunk: 1
[2025-10-06T19:29:30.678+0000] {connection.py:788} INFO - closed
[2025-10-06T19:29:30.771+0000] {connection.py:794} INFO - No async queries seem to be running, deleting session
[2025-10-06T19:29:30.847+0000] {python.py:240} INFO - Done. Returned value was: None
[2025-10-06T19:29:30.871+0000] {taskinstance.py:340} INFO - ::group::Post task execution logs
[2025-10-06T19:29:30.872+0000] {taskinstance.py:352} INFO - Marking task as SUCCESS. dag_id=stocks_prediction_analysis, task_id=load_records, run_id=manual__2025-10-06T19:21:36.081433+00:00, execution_date=20251006T192136, start_date=20251006T192139, end_date=20251006T192930
[2025-10-06T19:29:30.917+0000] {local_task_job_runner.py:266} INFO - Task exited with return code 0
[2025-10-06T19:29:30.936+0000] {taskinstance.py:3900} INFO - 1 downstream tasks scheduled from follow-on schedule check
[2025-10-06T19:29:30.937+0000] {local_task_job_runner.py:245} INFO - ::endgroup::
