[2025-10-03T06:10:33.635+0000] {local_task_job_runner.py:123} INFO - ::group::Pre task execution logs
[2025-10-03T06:10:33.642+0000] {taskinstance.py:2612} INFO - Dependencies all met for dep_context=non-requeueable deps ti=<TaskInstance: Stock_analysis.load_records manual__2025-10-03T06:10:31.640649+00:00 [queued]>
[2025-10-03T06:10:33.646+0000] {taskinstance.py:2612} INFO - Dependencies all met for dep_context=requeueable deps ti=<TaskInstance: Stock_analysis.load_records manual__2025-10-03T06:10:31.640649+00:00 [queued]>
[2025-10-03T06:10:33.647+0000] {taskinstance.py:2865} INFO - Starting attempt 1 of 1
[2025-10-03T06:10:33.652+0000] {taskinstance.py:2888} INFO - Executing <Task(_PythonDecoratedOperator): load_records> on 2025-10-03 06:10:31.640649+00:00
[2025-10-03T06:10:33.655+0000] {logging_mixin.py:190} WARNING - /home/***/.local/lib/python3.12/site-packages/***/task/task_runner/standard_task_runner.py:70 DeprecationWarning: This process (pid=7366) is multi-threaded, use of fork() may lead to deadlocks in the child.
[2025-10-03T06:10:33.656+0000] {standard_task_runner.py:72} INFO - Started process 7374 to run task
[2025-10-03T06:10:33.656+0000] {standard_task_runner.py:104} INFO - Running: ['***', 'tasks', 'run', 'Stock_analysis', 'load_records', 'manual__2025-10-03T06:10:31.640649+00:00', '--job-id', '46', '--raw', '--subdir', 'DAGS_FOLDER/Data226_Kruthika_V_HW5.py', '--cfg-path', '/tmp/tmp1mc15dn_']
[2025-10-03T06:10:33.657+0000] {standard_task_runner.py:105} INFO - Job 46: Subtask load_records
[2025-10-03T06:10:33.671+0000] {task_command.py:467} INFO - Running <TaskInstance: Stock_analysis.load_records manual__2025-10-03T06:10:31.640649+00:00 [running]> on host b99170a1b783
[2025-10-03T06:10:33.699+0000] {taskinstance.py:3131} INFO - Exporting env vars: AIRFLOW_CTX_DAG_OWNER='***' AIRFLOW_CTX_DAG_ID='Stock_analysis' AIRFLOW_CTX_TASK_ID='load_records' AIRFLOW_CTX_EXECUTION_DATE='2025-10-03T06:10:31.640649+00:00' AIRFLOW_CTX_TRY_NUMBER='1' AIRFLOW_CTX_DAG_RUN_ID='manual__2025-10-03T06:10:31.640649+00:00'
[2025-10-03T06:10:33.700+0000] {taskinstance.py:731} INFO - ::endgroup::
[2025-10-03T06:10:33.705+0000] {base.py:84} INFO - Retrieving connection 'snowflake_conn'
[2025-10-03T06:10:33.705+0000] {connection.py:413} INFO - Snowflake Connector for Python Version: 3.12.1, Python Version: 3.12.5, Platform: Linux-6.10.14-linuxkit-aarch64-with-glibc2.36
[2025-10-03T06:10:33.705+0000] {connection.py:1196} INFO - Connecting to GLOBAL Snowflake domain
[2025-10-03T06:10:33.706+0000] {connection.py:1277} INFO - This connection is in OCSP Fail Open Mode. TLS Certificates would be checked for validity and revocation status. Any other Certificate Revocation related exceptions or OCSP Responder failures would be disregarded in favor of connectivity.
[2025-10-03T06:10:34.257+0000] {base.py:84} INFO - Retrieving connection 'snowflake_conn'
[2025-10-03T06:10:34.258+0000] {connection.py:413} INFO - Snowflake Connector for Python Version: 3.12.1, Python Version: 3.12.5, Platform: Linux-6.10.14-linuxkit-aarch64-with-glibc2.36
[2025-10-03T06:10:34.258+0000] {connection.py:1196} INFO - Connecting to GLOBAL Snowflake domain
[2025-10-03T06:10:34.259+0000] {connection.py:1277} INFO - This connection is in OCSP Fail Open Mode. TLS Certificates would be checked for validity and revocation status. Any other Certificate Revocation related exceptions or OCSP Responder failures would be disregarded in favor of connectivity.
[2025-10-03T06:10:34.869+0000] {cursor.py:1156} INFO - Number of results in first chunk: 1
[2025-10-03T06:12:28.932+0000] {taskinstance.py:3310} ERROR - Task failed with exception
Traceback (most recent call last):
  File "/opt/airflow/dags/Data226_Kruthika_V_HW5.py", line 82, in load_records
    cur.commit()
    ^^^^^^^^^^
AttributeError: 'SnowflakeCursor' object has no attribute 'commit'

During handling of the above exception, another exception occurred:

Traceback (most recent call last):
  File "/home/airflow/.local/lib/python3.12/site-packages/airflow/models/taskinstance.py", line 767, in _execute_task
    result = _execute_callable(context=context, **execute_callable_kwargs)
             ^^^^^^^^^^^^^^^^^^^^^^^^^^^^^^^^^^^^^^^^^^^^^^^^^^^^^^^^^^^^^
  File "/home/airflow/.local/lib/python3.12/site-packages/airflow/models/taskinstance.py", line 733, in _execute_callable
    return ExecutionCallableRunner(
           ^^^^^^^^^^^^^^^^^^^^^^^^
  File "/home/airflow/.local/lib/python3.12/site-packages/airflow/utils/operator_helpers.py", line 252, in run
    return self.func(*args, **kwargs)
           ^^^^^^^^^^^^^^^^^^^^^^^^^^
  File "/home/airflow/.local/lib/python3.12/site-packages/airflow/models/baseoperator.py", line 406, in wrapper
    return func(self, *args, **kwargs)
           ^^^^^^^^^^^^^^^^^^^^^^^^^^^
  File "/home/airflow/.local/lib/python3.12/site-packages/airflow/decorators/base.py", line 266, in execute
    return_value = super().execute(context)
                   ^^^^^^^^^^^^^^^^^^^^^^^^
  File "/home/airflow/.local/lib/python3.12/site-packages/airflow/models/baseoperator.py", line 406, in wrapper
    return func(self, *args, **kwargs)
           ^^^^^^^^^^^^^^^^^^^^^^^^^^^
  File "/home/airflow/.local/lib/python3.12/site-packages/airflow/operators/python.py", line 238, in execute
    return_value = self.execute_callable()
                   ^^^^^^^^^^^^^^^^^^^^^^^
  File "/home/airflow/.local/lib/python3.12/site-packages/airflow/operators/python.py", line 256, in execute_callable
    return runner.run(*self.op_args, **self.op_kwargs)
           ^^^^^^^^^^^^^^^^^^^^^^^^^^^^^^^^^^^^^^^^^^^
  File "/home/airflow/.local/lib/python3.12/site-packages/airflow/utils/operator_helpers.py", line 252, in run
    return self.func(*args, **kwargs)
           ^^^^^^^^^^^^^^^^^^^^^^^^^^
  File "/opt/airflow/dags/Data226_Kruthika_V_HW5.py", line 85, in load_records
    cur.rollback()
    ^^^^^^^^^^^^
AttributeError: 'SnowflakeCursor' object has no attribute 'rollback'
[2025-10-03T06:12:28.957+0000] {taskinstance.py:1225} INFO - Marking task as FAILED. dag_id=Stock_analysis, task_id=load_records, run_id=manual__2025-10-03T06:10:31.640649+00:00, execution_date=20251003T061031, start_date=20251003T061033, end_date=20251003T061228
[2025-10-03T06:12:28.967+0000] {taskinstance.py:340} INFO - ::group::Post task execution logs
[2025-10-03T06:12:28.967+0000] {standard_task_runner.py:124} ERROR - Failed to execute job 46 for task load_records ('SnowflakeCursor' object has no attribute 'rollback'; 7374)
Traceback (most recent call last):
  File "/opt/airflow/dags/Data226_Kruthika_V_HW5.py", line 82, in load_records
    cur.commit()
    ^^^^^^^^^^
AttributeError: 'SnowflakeCursor' object has no attribute 'commit'

During handling of the above exception, another exception occurred:

Traceback (most recent call last):
  File "/home/airflow/.local/lib/python3.12/site-packages/airflow/task/task_runner/standard_task_runner.py", line 117, in _start_by_fork
    ret = args.func(args, dag=self.dag)
          ^^^^^^^^^^^^^^^^^^^^^^^^^^^^^
  File "/home/airflow/.local/lib/python3.12/site-packages/airflow/cli/cli_config.py", line 49, in command
    return func(*args, **kwargs)
           ^^^^^^^^^^^^^^^^^^^^^
  File "/home/airflow/.local/lib/python3.12/site-packages/airflow/utils/cli.py", line 115, in wrapper
    return f(*args, **kwargs)
           ^^^^^^^^^^^^^^^^^^
  File "/home/airflow/.local/lib/python3.12/site-packages/airflow/cli/commands/task_command.py", line 483, in task_run
    task_return_code = _run_task_by_selected_method(args, _dag, ti)
                       ^^^^^^^^^^^^^^^^^^^^^^^^^^^^^^^^^^^^^^^^^^^^
  File "/home/airflow/.local/lib/python3.12/site-packages/airflow/cli/commands/task_command.py", line 256, in _run_task_by_selected_method
    return _run_raw_task(args, ti)
           ^^^^^^^^^^^^^^^^^^^^^^^
  File "/home/airflow/.local/lib/python3.12/site-packages/airflow/cli/commands/task_command.py", line 341, in _run_raw_task
    return ti._run_raw_task(
           ^^^^^^^^^^^^^^^^^
  File "/home/airflow/.local/lib/python3.12/site-packages/airflow/utils/session.py", line 97, in wrapper
    return func(*args, session=session, **kwargs)
           ^^^^^^^^^^^^^^^^^^^^^^^^^^^^^^^^^^^^^^
  File "/home/airflow/.local/lib/python3.12/site-packages/airflow/models/taskinstance.py", line 3004, in _run_raw_task
    return _run_raw_task(
           ^^^^^^^^^^^^^^
  File "/home/airflow/.local/lib/python3.12/site-packages/airflow/models/taskinstance.py", line 273, in _run_raw_task
    TaskInstance._execute_task_with_callbacks(
  File "/home/airflow/.local/lib/python3.12/site-packages/airflow/models/taskinstance.py", line 3158, in _execute_task_with_callbacks
    result = self._execute_task(context, task_orig)
             ^^^^^^^^^^^^^^^^^^^^^^^^^^^^^^^^^^^^^^
  File "/home/airflow/.local/lib/python3.12/site-packages/airflow/models/taskinstance.py", line 3182, in _execute_task
    return _execute_task(self, context, task_orig)
           ^^^^^^^^^^^^^^^^^^^^^^^^^^^^^^^^^^^^^^^
  File "/home/airflow/.local/lib/python3.12/site-packages/airflow/models/taskinstance.py", line 767, in _execute_task
    result = _execute_callable(context=context, **execute_callable_kwargs)
             ^^^^^^^^^^^^^^^^^^^^^^^^^^^^^^^^^^^^^^^^^^^^^^^^^^^^^^^^^^^^^
  File "/home/airflow/.local/lib/python3.12/site-packages/airflow/models/taskinstance.py", line 733, in _execute_callable
    return ExecutionCallableRunner(
           ^^^^^^^^^^^^^^^^^^^^^^^^
  File "/home/airflow/.local/lib/python3.12/site-packages/airflow/utils/operator_helpers.py", line 252, in run
    return self.func(*args, **kwargs)
           ^^^^^^^^^^^^^^^^^^^^^^^^^^
  File "/home/airflow/.local/lib/python3.12/site-packages/airflow/models/baseoperator.py", line 406, in wrapper
    return func(self, *args, **kwargs)
           ^^^^^^^^^^^^^^^^^^^^^^^^^^^
  File "/home/airflow/.local/lib/python3.12/site-packages/airflow/decorators/base.py", line 266, in execute
    return_value = super().execute(context)
                   ^^^^^^^^^^^^^^^^^^^^^^^^
  File "/home/airflow/.local/lib/python3.12/site-packages/airflow/models/baseoperator.py", line 406, in wrapper
    return func(self, *args, **kwargs)
           ^^^^^^^^^^^^^^^^^^^^^^^^^^^
  File "/home/airflow/.local/lib/python3.12/site-packages/airflow/operators/python.py", line 238, in execute
    return_value = self.execute_callable()
                   ^^^^^^^^^^^^^^^^^^^^^^^
  File "/home/airflow/.local/lib/python3.12/site-packages/airflow/operators/python.py", line 256, in execute_callable
    return runner.run(*self.op_args, **self.op_kwargs)
           ^^^^^^^^^^^^^^^^^^^^^^^^^^^^^^^^^^^^^^^^^^^
  File "/home/airflow/.local/lib/python3.12/site-packages/airflow/utils/operator_helpers.py", line 252, in run
    return self.func(*args, **kwargs)
           ^^^^^^^^^^^^^^^^^^^^^^^^^^
  File "/opt/airflow/dags/Data226_Kruthika_V_HW5.py", line 85, in load_records
    cur.rollback()
    ^^^^^^^^^^^^
AttributeError: 'SnowflakeCursor' object has no attribute 'rollback'
[2025-10-03T06:12:29.003+0000] {local_task_job_runner.py:266} INFO - Task exited with return code 1
[2025-10-03T06:12:29.016+0000] {taskinstance.py:3900} INFO - 0 downstream tasks scheduled from follow-on schedule check
[2025-10-03T06:12:29.016+0000] {local_task_job_runner.py:245} INFO - ::endgroup::
